<?xml version="1.0" encoding="utf-8"?><testsuites name="pytest tests"><testsuite name="pytest" errors="1" failures="0" skipped="0" tests="1" time="0.152" timestamp="2025-09-16T13:44:38.204154+08:00" hostname="lichuansongdeMacBook-Air.local"><testcase time="0.048" /><testcase classname="pytest" name="internal" time="0.000"><error message="internal error">Traceback (most recent call last):
  File "/Users/lichuansong/Library/Python/3.9/lib/python/site-packages/_pytest/main.py", line 289, in wrap_session
    session.exitstatus = doit(config, session) or 0
  File "/Users/lichuansong/Library/Python/3.9/lib/python/site-packages/_pytest/main.py", line 343, in _main
    config.hook.pytest_runtestloop(session=session)
  File "/Users/lichuansong/Library/Python/3.9/lib/python/site-packages/pluggy/_hooks.py", line 512, in __call__
    return self._hookexec(self.name, self._hookimpls.copy(), kwargs, firstresult)
  File "/Users/lichuansong/Library/Python/3.9/lib/python/site-packages/pluggy/_manager.py", line 120, in _hookexec
    return self._inner_hookexec(hook_name, methods, kwargs, firstresult)
  File "/Users/lichuansong/Library/Python/3.9/lib/python/site-packages/pluggy/_callers.py", line 167, in _multicall
    raise exception
  File "/Users/lichuansong/Library/Python/3.9/lib/python/site-packages/pluggy/_callers.py", line 139, in _multicall
    teardown.throw(exception)
  File "/Users/lichuansong/Library/Python/3.9/lib/python/site-packages/_pytest/logging.py", line 801, in pytest_runtestloop
    return (yield)  # Run all the tests.
  File "/Users/lichuansong/Library/Python/3.9/lib/python/site-packages/pluggy/_callers.py", line 139, in _multicall
    teardown.throw(exception)
  File "/Users/lichuansong/Library/Python/3.9/lib/python/site-packages/_pytest/terminal.py", line 688, in pytest_runtestloop
    result = yield
  File "/Users/lichuansong/Library/Python/3.9/lib/python/site-packages/pluggy/_callers.py", line 121, in _multicall
    res = hook_impl.function(*args)
  File "/Users/lichuansong/Library/Python/3.9/lib/python/site-packages/_pytest/main.py", line 367, in pytest_runtestloop
    item.config.hook.pytest_runtest_protocol(item=item, nextitem=nextitem)
  File "/Users/lichuansong/Library/Python/3.9/lib/python/site-packages/pluggy/_hooks.py", line 512, in __call__
    return self._hookexec(self.name, self._hookimpls.copy(), kwargs, firstresult)
  File "/Users/lichuansong/Library/Python/3.9/lib/python/site-packages/pluggy/_manager.py", line 120, in _hookexec
    return self._inner_hookexec(hook_name, methods, kwargs, firstresult)
  File "/Users/lichuansong/Library/Python/3.9/lib/python/site-packages/pluggy/_callers.py", line 167, in _multicall
    raise exception
  File "/Users/lichuansong/Library/Python/3.9/lib/python/site-packages/pluggy/_callers.py", line 139, in _multicall
    teardown.throw(exception)
  File "/Users/lichuansong/Library/Python/3.9/lib/python/site-packages/_pytest/warnings.py", line 90, in pytest_runtest_protocol
    return (yield)
  File "/Users/lichuansong/Library/Python/3.9/lib/python/site-packages/pluggy/_callers.py", line 139, in _multicall
    teardown.throw(exception)
  File "/Users/lichuansong/Library/Python/3.9/lib/python/site-packages/_pytest/assertion/__init__.py", line 192, in pytest_runtest_protocol
    return (yield)
  File "/Users/lichuansong/Library/Python/3.9/lib/python/site-packages/pluggy/_callers.py", line 139, in _multicall
    teardown.throw(exception)
  File "/Users/lichuansong/Library/Python/3.9/lib/python/site-packages/_pytest/unittest.py", line 475, in pytest_runtest_protocol
    return (yield)
  File "/Users/lichuansong/Library/Python/3.9/lib/python/site-packages/pluggy/_callers.py", line 139, in _multicall
    teardown.throw(exception)
  File "/Users/lichuansong/Library/Python/3.9/lib/python/site-packages/_pytest/faulthandler.py", line 88, in pytest_runtest_protocol
    return (yield)
  File "/Users/lichuansong/Library/Python/3.9/lib/python/site-packages/pluggy/_callers.py", line 121, in _multicall
    res = hook_impl.function(*args)
  File "/Users/lichuansong/Library/Python/3.9/lib/python/site-packages/_pytest/runner.py", line 117, in pytest_runtest_protocol
    runtestprotocol(item, nextitem=nextitem)
  File "/Users/lichuansong/Library/Python/3.9/lib/python/site-packages/_pytest/runner.py", line 136, in runtestprotocol
    reports.append(call_and_report(item, "call", log))
  File "/Users/lichuansong/Library/Python/3.9/lib/python/site-packages/_pytest/runner.py", line 248, in call_and_report
    report: TestReport = ihook.pytest_runtest_makereport(item=item, call=call)
  File "/Users/lichuansong/Library/Python/3.9/lib/python/site-packages/pluggy/_hooks.py", line 512, in __call__
    return self._hookexec(self.name, self._hookimpls.copy(), kwargs, firstresult)
  File "/Users/lichuansong/Library/Python/3.9/lib/python/site-packages/pluggy/_manager.py", line 120, in _hookexec
    return self._inner_hookexec(hook_name, methods, kwargs, firstresult)
  File "/Users/lichuansong/Library/Python/3.9/lib/python/site-packages/pluggy/_callers.py", line 167, in _multicall
    raise exception
  File "/Users/lichuansong/Library/Python/3.9/lib/python/site-packages/pluggy/_callers.py", line 152, in _multicall
    teardown.send(result)
  File "/Users/lichuansong/Library/Python/3.9/lib/python/site-packages/pluggy/_callers.py", line 43, in run_old_style_hookwrapper
    teardown.send(result)
  File "/Users/lichuansong/Desktop/projects/wlxj_python/tests/conftest.py", line 398, in pytest_runtest_makereport
    rep.test_file = str(item.fspath.relative_to(item.config.rootdir))
AttributeError: 'LocalPath' object has no attribute 'relative_to'</error></testcase></testsuite></testsuites>